WARNING  urllib3.connectionpool:connectionpool.py:871 Retrying (Retry(total=2, connect=None, read=None, redirect=None, status=None)) after connection broken by 'ConnectTimeoutError(<urllib3.connection.HTTPConnection object at 0x7fa99c1f3690>, 'Connection to 192.168.1.5 timed out. (connect timeout=None)')': /wd/hub/session
WARNING  urllib3.connectionpool:connectionpool.py:871 Retrying (Retry(total=1, connect=None, read=None, redirect=None, status=None)) after connection broken by 'ConnectTimeoutError(<urllib3.connection.HTTPConnection object at 0x7fa99c1f3f90>, 'Connection to 192.168.1.5 timed out. (connect timeout=None)')': /wd/hub/session
WARNING  urllib3.connectionpool:connectionpool.py:871 Retrying (Retry(total=0, connect=None, read=None, redirect=None, status=None)) after connection broken by 'ConnectTimeoutError(<urllib3.connection.HTTPConnection object at 0x7fa99c1f4b50>, 'Connection to 192.168.1.5 timed out. (connect timeout=None)')': /wd/hub/session